Workbook

Sheet Hoja1
A1: Cod_Expre | B1: Nombre | C1: Cod_Suc | D1: Sucursal | E1: Cod_Prov | F1: Direccion | G1: Localidad | H1: =+VLOOKUP(G1,Agrupacion!A:B,2,0) -> Agrupador | I1: Zona Agrupador | J1: C_Post | K1: Telefono | L1: Notas | M1: inactivo
A2: 1 | B2: OLIVA | C2: 1 | D2: JOSE RODO 6255 (COMUNA 9 ) | E2: 2 | F2: JOSE RODO 6255 | G2: MATADEROS | H2: =_xlfn.IFNA(+VLOOKUP(G2,Agrupacion!A:B,2,0),"") -> AGRUPADOR 3 | I2: =_xlfn.IFNA(+VLOOKUP(G2,Agrupacion!A:C,3,0),"") -> CABA SUR II | J2: 1440 | M2: FALSO
A3: 2 | B3: EL RAPIDO | C3: 1 | D3: VELEZ SARSFIELD 1649 (COMUNA 4 ) CABA | E3: 2 | F3: VELEZ SARSFIELD 1649 | G3: BARRACAS | H3: =_xlfn.IFNA(+VLOOKUP(G3,Agrupacion!A:B,2,0),"") -> AGRUPADOR 2 | I3: =_xlfn.IFNA(+VLOOKUP(G3,Agrupacion!A:C,3,0),"") -> CABA SUR | J3: 1285 | K3: 4302-2328 | M3: FALSO
A4: 3 | B4: EL COLORADO | C4: 1 | D4: RIO CUARTO 1948 Y HERNANDARIAS - ( CAP. FED. ) | E4: 2 | F4: RIO CUARTO 1948 Y HERNANDARIAS | G4: VILLA SOLDATI | H4: =_xlfn.IFNA(+VLOOKUP(G4,Agrupacion!A:B,2,0),"") -> AGRUPADOR 3 | I4: =_xlfn.IFNA(+VLOOKUP(G4,Agrupacion!A:C,3,0),"") -> CABA SUR II | M4: FALSO
A5: 4 | B5: IMAZ S R L | C5: 1 | D5: PERGAMINO 3830 (COMUNA 8 ) CABA | E5: 2 | F5: PERGAMINO 3830 | G5: VILLA SOLDATI | H5: =_xlfn.IFNA(+VLOOKUP(G5,Agrupacion!A:B,2,0),"") -> AGRUPADOR 3 | I5: =_xlfn.IFNA(+VLOOKUP(G5,Agrupacion!A:C,3,0),"") -> CABA SUR II | J5: 1437 | K5: 4919-0267 / 0269 | M5: FALSO
A6: 5 | B6: J.E LOGISTICA ( ex gabelli) | C6: 1 | D6: ANCASTE 3111 - ( CAP. FED. ) | E6: 2 | F6: ANCASTE 3111 | G6: VILLA SOLDATI | H6: =_xlfn.IFNA(+VLOOKUP(G6,Agrupacion!A:B,2,0),"") -> AGRUPADOR 3 | I6: =_xlfn.IFNA(+VLOOKUP(G6,Agrupacion!A:C,3,0),"") -> CABA SUR II | K6: 4911-6562/6745 | M6: FALSO
A7: 6 | B7: ORLANDO MORRESI | C7: 1 | D7: CARLOS BERG 3591 ESQ FERRE (COMUNA 8 ) CABA | E7: 2 | F7: CARLOS BERG 3591 ESQ FERRE | G7: VILLA SOLDATI | H7: =_xlfn.IFNA(+VLOOKUP(G7,Agrupacion!A:B,2,0),"") -> AGRUPADOR 3 | I7: =_xlfn.IFNA(+VLOOKUP(G7,Agrupacion!A:C,3,0),"") -> CABA SUR II | J7: 1437 | K7: 4919-3200/0261-4212243 | M7: FALSO
A8: 7 | B8: TRANSPORTE RODRIGUEZ HNOS.SRL | C8: 1 | D8: AV. EREZCANO 3880 - ( CAP. FED. ) | E8: 2 | F8: AV. EREZCANO 3880 | G8: VILLA SOLDATI | H8: =_xlfn.IFNA(+VLOOKUP(G8,Agrupacion!A:B,2,0),"") -> AGRUPADOR 3 | I8: =_xlfn.IFNA(+VLOOKUP(G8,Agrupacion!A:C,3,0),"") -> CABA SUR II | J8: 1437 | K8: 4918-0004 | M8: FALSO
A9: 8 | B9: SZILAK | C9: 1 | D9: GRITO DE ASENCIO 3231 (COMUNA 4) CABA | E9: 2 | F9: GRITO DE ASENCIO 3231 | G9: PARQUE PATRICIOS | H9: =_xlfn.IFNA(+VLOOKUP(G9,Agrupacion!A:B,2,0),"") -> AGRUPADOR 2 | I9: =_xlfn.IFNA(+VLOOKUP(G9,Agrupacion!A:C,3,0),"") -> CABA SUR | J9: 1437 | K9: 4912-3903 / 3904 | M9: FALSO
A10: 9 | B10: BISONTE S R L | C10: 1 | D10: ROCA Y PERGAMINO MODULO 76 NAVE 3 (COMUNA 8 ) CABA | E10: 2 | F10: ROCA Y PERGAMINO MODULO 76 NAVE 3 | G10: VILLA SOLDATI | H10: =_xlfn.IFNA(+VLOOKUP(G10,Agrupacion!A:B,2,0),"") -> AGRUPADOR 3 | I10: =_xlfn.IFNA(+VLOOKUP(G10,Agrupacion!A:C,3,0),"") -> CABA SUR II | J10: 1437 | K10: 2206-2636 | M10: FALSO
A11: 10 | B11: GONZALEZ JUAN CARLOS | C11: 1 | D11: AV. INT. FRANCISCO RABANAL 2886 - ( CAPITAL FEDERAL ) | E11: 2 | F11: AV. INT. FRANCISCO RABANAL 2886 | G11: VILLA SOLDATI | H11: =_xlfn.IFNA(+VLOOKUP(G11,Agrupacion!A:B,2,0),"") -> AGRUPADOR 3 | I11: =_xlfn.IFNA(+VLOOKUP(G11,Agrupacion!A:C,3,0),"") -> CABA SUR II | J11: 1437 | K11: 4919-0075 | M11: FALSO
A12: 11 | B12: SCOR-DINA S.A. | C12: 1 | D12: AV. AMANCIO ALCORTA 3473 (COMUNA 4) CABA | E12: 2 | F12: AV. AMANCIO ALCORTA 3473 | G12: VILLA SOLDATI | H12: =_xlfn.IFNA(+VLOOKUP(G12,Agrupacion!A:B,2,0),"") -> AGRUPADOR 3 | I12: =_xlfn.IFNA(+VLOOKUP(G12,Agrupacion!A:C,3,0),"") -> CABA SUR II | J12: 1437 | K12: 4911-1728/1044/9514 | M12: FALSO
A13: 12 | B13: DEL NORTE INTEGRAL S.R.L. | C13: 1 | D13: ALBERTO EINSTEIM 1023 - ( CAPITAL FEDERAL ) | E13: 2 | F13: ALBERTO EINSTEIM 1023 | G13: VILLA SOLDATI | H13: =_xlfn.IFNA(+VLOOKUP(G13,Agrupacion!A:B,2,0),"") -> AGRUPADOR 3 | I13: =_xlfn.IFNA(+VLOOKUP(G13,Agrupacion!A:C,3,0),"") -> CABA SUR II | J13: 1437 | K13: 4911-0997 | M13: FALSO
A14: 13 | B14: SAN ESTEBAN SRL | C14: 1 | D14: AV.A.ALCORTA 1955 - ( P.PATRICIOS-CAPITAL ) | F14: AV.A.ALCORTA 1955 | G14: PARQUE PATRICIOS | H14: =_xlfn.IFNA(+VLOOKUP(G14,Agrupacion!A:B,2,0),"") -> AGRUPADOR 2 | I14: =_xlfn.IFNA(+VLOOKUP(G14,Agrupacion!A:C,3,0),"") -> CABA SUR | J14: 1284 | M14: FALSO
A15: 14 | B15: CRUZ DEL SUR SA. (Tapiales) | C15: 1 | D15: AU RICCHERI Y BOULOGNE SUR MER NAVE D3 - ( TAPIALES -BS AS ) | E15: 1 | F15: AU RICCHERI Y BOULOGNE SUR MER NAVE D3 | G15: TAPIALES | H15: =_xlfn.IFNA(+VLOOKUP(G15,Agrupacion!A:B,2,0),"") -> AGRUPADOR 3 | I15: =_xlfn.IFNA(+VLOOKUP(G15,Agrupacion!A:C,3,0),"") -> CABA SUR II | J15: 1771 | K15: 4480-6666 | L15: int 3 ( contrareembolso)_x000D_ LUNES A VIERNES 8 A 17 MERCADO CENTRAL | M15: FALSO
A16: 15 | B16: A.L.A. | C16: 1 | D16: VIRREY LINIERS 1350 - ( CAPITAL FEDERAL ) | E16: 2 | F16: VIRREY LINIERS 1350 | G16: BOEDO | H16: =_xlfn.IFNA(+VLOOKUP(G16,Agrupacion!A:B,2,0),"") -> AGRUPADOR 1 | I16: =_xlfn.IFNA(+VLOOKUP(G16,Agrupacion!A:C,3,0),"") -> CABA NORTE | J16: 1241 | M16: FALSO
A17: 16 | B17: QUIBIK LOGISTICA SAS (RIGAR) | C17: 1 | D17: JULIO TROXLER 3259 | E17: 2 | F17: JULIO TROXLER 3259 | G17: VILLA SOLDATI | H17: =_xlfn.IFNA(+VLOOKUP(G17,Agrupacion!A:B,2,0),"") -> AGRUPADOR 3 | I17: =_xlfn.IFNA(+VLOOKUP(G17,Agrupacion!A:C,3,0),"") -> CABA SUR II | J17: 1437 | K17: 4308-1568/4942-9711/9339 | L17: TEL. CORDOBA 0351-497-7000_x000D_ 011 24522816 - martin_x000D_ NOVIEMBRE 2025 CAMBIÓ DIRECCION | M17: FALSO
A18: 17 | B18: PICO S.R.L. | C18: 1 | D18: AUSTRALIA 2758 (COMUNA 4) CABA | E18: 2 | F18: AUSTRALIA 2758 | G18: BARRACAS | H18: =_xlfn.IFNA(+VLOOKUP(G18,Agrupacion!A:B,2,0),"") -> AGRUPADOR 2 | I18: =_xlfn.IFNA(+VLOOKUP(G18,Agrupacion!A:C,3,0),"") -> CABA SUR | J18: 1437 | K18: 4303-3130 | M18: FALSO
A19: 18 | B19: MORABITO SRL | C19: 1 | D19: LOS PATOS 2577 (COMUNA 4 ) CABA | E19: 2 | F19: LOS PATOS 2577 | G19: BARRACAS | H19: =_xlfn.IFNA(+VLOOKUP(G19,Agrupacion!A:B,2,0),"") -> AGRUPADOR 2 | I19: =_xlfn.IFNA(+VLOOKUP(G19,Agrupacion!A:C,3,0),"") -> CABA SUR | J19: 1284 | K19: 4942-6686 / 2628 | M19: FALSO
A20: 19 | B20: FRASER TRANSPORTE | C20: 1 | D20: CNEL.M.CHILAVERT 3258 (COMUNA 8) CABA | E20: 2 | F20: CNEL.M.CHILAVERT 3258 | G20: VILLA SOLDATI | H20: =_xlfn.IFNA(+VLOOKUP(G20,Agrupacion!A:B,2,0),"") -> AGRUPADOR 3 | I20: =_xlfn.IFNA(+VLOOKUP(G20,Agrupacion!A:C,3,0),"") -> CABA SUR II | J20: 1437 | K20: 4919-1368 | L20: horario de 8 a 17 hs | M20: FALSO
A21: 20 | B21: RUTA SUR | C21: 1 | D21: SALOM 667 - ( CAPITAL FEDERAL ) | E21: 2 | F21: SALOM 667 | G21: ESTACION SOLA | H21: =_xlfn.IFNA(+VLOOKUP(G21,Agrupacion!A:B,2,0),"") -> AGRUPADOR 3 | I21: =_xlfn.IFNA(+VLOOKUP(G21,Agrupacion!A:C,3,0),"") -> CABA SUR II | J21: 1277 | K21: 4302-1143 | M21: FALSO
A22: 21 | B22: ZIEGLER TRANSPORTACIONES SA. | C22: 1 | D22: JOSE CORTEJARENA 2954 - ( P.PATRICIOS-CAPITAL ) | F22: JOSE CORTEJARENA 2954 | G22: PARQUE PATRICIOS | H22: =_xlfn.IFNA(+VLOOKUP(G22,Agrupacion!A:B,2,0),"") -> AGRUPADOR 2 | I22: =_xlfn.IFNA(+VLOOKUP(G22,Agrupacion!A:C,3,0),"") -> CABA SUR | J22: 1437 | M22: FALSO
A23: 22 | B23: CONTINENTAL | C23: 1 | D23: C.M.RAMIREZ 2204 - ( SOLDATI-CAPITAL ) | F23: C.M.RAMIREZ 2204 | G23: VILLA SOLDATI | H23: =_xlfn.IFNA(+VLOOKUP(G23,Agrupacion!A:B,2,0),"") -> AGRUPADOR 3 | I23: =_xlfn.IFNA(+VLOOKUP(G23,Agrupacion!A:C,3,0),"") -> CABA SUR II | J23: 1437 | M23: FALSO
A24: 23 | B24: ORO BLANCO | C24: 1 | D24: RIVERA INDARTE 2749 (COMUNA 8 ) CABA | E24: 2 | F24: RIVERA INDARTE 2749 | G24: VILLA SOLDATI | H24: =_xlfn.IFNA(+VLOOKUP(G24,Agrupacion!A:B,2,0),"") -> AGRUPADOR 3 | I24: =_xlfn.IFNA(+VLOOKUP(G24,Agrupacion!A:C,3,0),"") -> CABA SUR II | J24: 1437 | K24: 4918-2649 | M24: FALSO
A25: 24 | B25: PRADA TRANSPORTE | C25: 1 | D25: VILLARINO 2375 (COMUNA 4) CABA | E25: 2 | F25: VILLARINO 2375 | G25: BARRACAS | H25: =_xlfn.IFNA(+VLOOKUP(G25,Agrupacion!A:B,2,0),"") -> AGRUPADOR 2 | I25: =_xlfn.IFNA(+VLOOKUP(G25,Agrupacion!A:C,3,0),"") -> CABA SUR | J25: 1273 | K25: (011) 302 7162 / (011) 15 6885 8338 | M25: FALSO
A26: 26 | B26: MANENTI JULIO E HIJOS | C26: 1 | D26: DR. LUIS PEDRO BALIÑA 4060 - ( PARQUE PATRICIOS ) | E26: 2 | F26: DR. LUIS PEDRO BALIÑA 4060 | G26: PARQUE PATRICIOS | H26: =_xlfn.IFNA(+VLOOKUP(G26,Agrupacion!A:B,2,0),"") -> AGRUPADOR 2 | I26: =_xlfn.IFNA(+VLOOKUP(G26,Agrupacion!A:C,3,0),"") -> CABA SUR | J26: 1437 | K26: 4912-2164 / 4911-8552 | M26: FALSO
A27: 27 | B27: COPAR | C27: 1 | D27: FERRE 3254 - ( CABA ) | E27: 2 | F27: FERRE 3254 | G27: VILLA SOLDATI | H27: =_xlfn.IFNA(+VLOOKUP(G27,Agrupacion!A:B,2,0),"") -> AGRUPADOR 3 | I27: =_xlfn.IFNA(+VLOOKUP(G27,Agrupacion!A:C,3,0),"") -> CABA SUR II | J27: 1437 | K27: 4918-7424 / 8126 | M27: FALSO
A28: 28 | B28: MARAL SRL | C28: 1 | D28: CASTANON 3561 - ( P.PATRICIOS-CAPITAL ) | E28: 2 | F28: CASTANON 3561 | G28: PARQUE PATRICIOS | H28: =_xlfn.IFNA(+VLOOKUP(G28,Agrupacion!A:B,2,0),"") -> AGRUPADOR 2 | I28: =_xlfn.IFNA(+VLOOKUP(G28,Agrupacion!A:C,3,0),"") -> CABA SUR | J28: 1437 | M28: FALSO
A29: 29 | B29: SUD ATLANTICO S.R.L. | C29: 1 | D29: RAFAELA 4710 - ( CAPITAL FEDERAL ) | E29: 2 | F29: RAFAELA 4710 | G29: FLORES | H29: =_xlfn.IFNA(+VLOOKUP(G29,Agrupacion!A:B,2,0),"") -> AGRUPADOR 1 | I29: =_xlfn.IFNA(+VLOOKUP(G29,Agrupacion!A:C,3,0),"") -> CABA NORTE | J29: 1407 | K29: 4674-1777 | M29: FALSO
A30: 30 | B30: NAPOSTA | C30: 1 | D30: C.T.C. PERGAMINO 3751 NAVE 2 MOD 84 - ( CAPITAL FEDERAL ) | E30: 2 | F30: C.T.C. PERGAMINO 3751 NAVE 2 MOD 84 | G30: VILLA SOLDATI | H30: =_xlfn.IFNA(+VLOOKUP(G30,Agrupacion!A:B,2,0),"") -> AGRUPADOR 3 | I30: =_xlfn.IFNA(+VLOOKUP(G30,Agrupacion!A:C,3,0),"") -> CABA SUR II | J30: 1437 | K30: 2206-2640 | M30: FALSO
A31: 31 | B31: LA TRANSPORTADORA | C31: 1 | D31: USPALLATA 2638 - ( P.PATRICIOS-CAPITAL ) | E31: 2 | F31: USPALLATA 2638 | G31: PARQUE PATRICIOS | H31: =_xlfn.IFNA(+VLOOKUP(G31,Agrupacion!A:B,2,0),"") -> AGRUPADOR 2 | I31: =_xlfn.IFNA(+VLOOKUP(G31,Agrupacion!A:C,3,0),"") -> CABA SUR | J31: 1437 | K31: 4942-6684 | M31: FALSO
A32: 32 | B32: BAIRES LOGISTICA | C32: 1 | D32: PORTELA 3479 - ( POMPEYA ) | E32: 2 | F32: PORTELA 3479 | G32: POMPEYA | H32: =_xlfn.IFNA(+VLOOKUP(G32,Agrupacion!A:B,2,0),"") -> AGRUPADOR 2 | I32: =_xlfn.IFNA(+VLOOKUP(G32,Agrupacion!A:C,3,0),"") -> CABA SUR | J32: 1437 | K32: 4919-0991/6148 | M32: FALSO
A33: 33 | B33: BRIO | C33: 1 | D33: SAN PEDRITO 3731 (COMUNA 8) CABA | E33: 2 | F33: SAN PEDRITO 3731 | G33: VILLA SOLDATI | H33: =_xlfn.IFNA(+VLOOKUP(G33,Agrupacion!A:B,2,0),"") -> AGRUPADOR 3 | I33: =_xlfn.IFNA(+VLOOKUP(G33,Agrupacion!A:C,3,0),"") -> CABA SUR II | J33: 1437 | K33: 4918-2224 | M33: FALSO
A34: 34 | B34: BENOZA S.R.L. | C34: 1 | D34: CACHIMAYO 1836 - ( PQUE.CHACABUCO-CAPIT ) | E34: 2 | F34: CACHIMAYO 1836 | G34: PARQUE CHACABUCO | H34: =_xlfn.IFNA(+VLOOKUP(G34,Agrupacion!A:B,2,0),"") -> AGRUPADOR 1 | I34: =_xlfn.IFNA(+VLOOKUP(G34,Agrupacion!A:C,3,0),"") -> CABA NORTE | J34: 1424 | M34: FALSO
A35: 35 | B35: SEDICA S.A. - TRADELOG | C35: 1 | D35: PERGAMINO 3751 MOD 71 A 75 nave (c) (COMUNA 8 ) CABA | E35: 2 | F35: PERGAMINO 3751 MOD 71 A 75 nave (c) | G35: VILLA SOLDATI | H35: =_xlfn.IFNA(+VLOOKUP(G35,Agrupacion!A:B,2,0),"") -> AGRUPADOR 3 | I35: =_xlfn.IFNA(+VLOOKUP(G35,Agrupacion!A:C,3,0),"") -> CABA SUR II | J35: 1437 | K35: 5091-6600/3754-7206 | M35: FALSO
A36: 36 | B36: NANDUBAY | C36: 1 | D36: PERGAMINO 3751 MOD 64/65 NAVE 3 (COMUNA 8) CABA | E36: 2 | F36: C.T.C. PERGAMINO 3751 MOD 64/65 NAVE 3 | G36: VILLA SOLDATI | H36: =_xlfn.IFNA(+VLOOKUP(G36,Agrupacion!A:B,2,0),"") -> AGRUPADOR 3 | I36: =_xlfn.IFNA(+VLOOKUP(G36,Agrupacion!A:C,3,0),"") -> CABA SUR II | J36: 1437 | K36: 3754-7220 | M36: FALSO
A37: 37 | B37: RODAR | C37: 1 | D37: LAVARDEN 740 - ( P.PATRICIOS-CAPITAL ) | E37: 2 | F37: LAVARDEN 740 | G37: PARQUE PATRICIOS | H37: =_xlfn.IFNA(+VLOOKUP(G37,Agrupacion!A:B,2,0),"") -> AGRUPADOR 2 | I37: =_xlfn.IFNA(+VLOOKUP(G37,Agrupacion!A:C,3,0),"") -> CABA SUR | J37: 1437 | M37: FALSO
A38: 38 | B38: ALMAFUERTE S.R.L. | C38: 1 | D38: CHARRUA 3520 - ( CAPITAL FEDERAL ) | E38: 2 | F38: CHARRUA 3520 | G38: VILLA SOLDATI | H38: =_xlfn.IFNA(+VLOOKUP(G38,Agrupacion!A:B,2,0),"") -> AGRUPADOR 3 | I38: =_xlfn.IFNA(+VLOOKUP(G38,Agrupacion!A:C,3,0),"") -> CABA SUR II | J38: 1437 | K38: 4918-6278 | M38: FALSO
A39: 39 | B39: DEPOSITO PROALSA | C39: 1 | D39: FORMOSA 3486 Y PCIA.UNIDA - ( LOMAS DEL MIRADOR ) | E39: 1 | F39: FORMOSA 3486 Y PCIA.UNIDA | G39: LOMAS DEL MIRADOR | H39: =_xlfn.IFNA(+VLOOKUP(G39,Agrupacion!A:B,2,0),"") -> AGRUPADOR 6 | I39: =_xlfn.IFNA(+VLOOKUP(G39,Agrupacion!A:C,3,0),"") -> GBA OESTE | J39: 1752 | M39: FALSO
A40: 40 | B40: EXPRESO FUEGUINO | C40: 1 | D40: AUSTRALIA 2838 (COMUNA 4) CABA | E40: 2 | F40: AUSTRALIA 2838 | G40: BARRACAS | H40: =_xlfn.IFNA(+VLOOKUP(G40,Agrupacion!A:B,2,0),"") -> AGRUPADOR 2 | I40: =_xlfn.IFNA(+VLOOKUP(G40,Agrupacion!A:C,3,0),"") -> CABA SUR | J40: 1296 | K40: 4303-6222 | L40: HORARIO 8 A 12.30 Y 13 A 17 HS. | M40: FALSO
...

Sheet Agrupacion
A1: Localidad | B1: Agrupador | C1: Zona Agrupador
A2: BOEDO | B2: AGRUPADOR 1 | C2: CABA NORTE
A3: FLORES | B3: AGRUPADOR 1 | C3: CABA NORTE
A4: LINIERS | B4: AGRUPADOR 1 | C4: CABA NORTE
A5: PALERMO | B5: AGRUPADOR 1 | C5: CABA NORTE
A6: PARQUE CHACABUCO | B6: AGRUPADOR 1 | C6: CABA NORTE
A7: PATERNAL | B7: AGRUPADOR 1 | C7: CABA NORTE
A8: RETIRO | B8: AGRUPADOR 1 | C8: CABA NORTE
A9: VILLA DEL PARQUE | B9: AGRUPADOR 1 | C9: CABA NORTE
A10: VILLA CRESPO | B10: AGRUPADOR 1 | C10: CABA NORTE
A11: AVELLANEDA 2 | B11: AGRUPADOR 2 | C11: CABA SUR
A12: BARRACAS | B12: AGRUPADOR 2 | C12: CABA SUR
... A64: RETIRA | B64: RETIRA | C64: -
